INFO     pytest_operator.plugin:plugin.py:929 Model status:

Model                            Controller  Cloud/Region         Version  SLA          Timestamp
test-charm-metrics-failure-n7sr  lxd         localhost/localhost  3.6.1    unsupported  13:51:02Z

App                          Version  Status  Scale  Charm                        Channel      Rev  Exposed  Message
github-runner-image-builder           active      1  github-runner-image-builder  latest/edge    2  no       
test-l5whup2h                         active      1  github-runner                               0  yes      

Unit                            Workload  Agent  Machine  Public address  Ports     Message
github-runner-image-builder/0*  active    idle   0        10.16.162.250             
test-l5whup2h/0*                active    idle   1        10.16.162.173   8080/tcp  

Machine  State    Address        Inst id        Base          AZ  Message
0        started  10.16.162.250  juju-51d22c-0  ubuntu@22.04      Running
1        started  10.16.162.173  juju-51d22c-1  ubuntu@22.04      Running

INFO     pytest_operator.plugin:plugin.py:935 Juju error logs:

machine-0: 13:42:17 ERROR juju.worker.dependency "lxd-container-provisioner" manifold worker returned unexpected error: container types not yet available
machine-0: 13:42:17 ERROR juju.worker.dependency "kvm-container-provisioner" manifold worker returned unexpected error: container types not yet available
unit-github-runner-image-builder-0: 13:42:17 ERROR juju.worker.meterstatus error running "meter-status-changed": charm missing from disk
machine-1: 13:46:04 ERROR juju.worker.dependency "lxd-container-provisioner" manifold worker returned unexpected error: container types not yet available
machine-1: 13:46:04 ERROR juju.worker.dependency "kvm-container-provisioner" manifold worker returned unexpected error: container types not yet available
unit-test-l5whup2h-0: 13:46:04 ERROR juju.worker.meterstatus error running "meter-status-changed": charm missing from disk
unit-test-l5whup2h-0: 13:46:20 CRITICAL unit.test-l5whup2h/0.juju-log test mode is enabled
unit-test-l5whup2h-0: 13:46:22 CRITICAL unit.test-l5whup2h/0.juju-log test mode is enabled
unit-test-l5whup2h-0: 13:46:26 CRITICAL unit.test-l5whup2h/0.juju-log image:0: test mode is enabled
unit-test-l5whup2h-0: 13:46:27 CRITICAL unit.test-l5whup2h/0.juju-log test mode is enabled
unit-test-l5whup2h-0: 13:46:29 CRITICAL unit.test-l5whup2h/0.juju-log test mode is enabled
unit-test-l5whup2h-0: 13:46:31 CRITICAL unit.test-l5whup2h/0.juju-log test mode is enabled
unit-test-l5whup2h-0: 13:46:33 CRITICAL unit.test-l5whup2h/0.juju-log test mode is enabled
unit-test-l5whup2h-0: 13:46:34 CRITICAL unit.test-l5whup2h/0.juju-log image:0: test mode is enabled
unit-test-l5whup2h-0: 13:46:35 CRITICAL unit.test-l5whup2h/0.juju-log image:0: test mode is enabled
unit-test-l5whup2h-0: 13:47:35 CRITICAL unit.test-l5whup2h/0.juju-log test mode is enabled
unit-test-l5whup2h-0: 13:47:36 CRITICAL unit.test-l5whup2h/0.juju-log test mode is enabled
unit-test-l5whup2h-0: 13:47:59 CRITICAL unit.test-l5whup2h/0.juju-log test mode is enabled
unit-test-l5whup2h-0: 13:48:39 CRITICAL unit.test-l5whup2h/0.juju-log test mode is enabled
unit-test-l5whup2h-0: 13:48:56 CRITICAL unit.test-l5whup2h/0.juju-log test mode is enabled
unit-test-l5whup2h-0: 13:49:47 CRITICAL unit.test-l5whup2h/0.juju-log test mode is enabled
unit-test-l5whup2h-0: 13:49:48 CRITICAL unit.test-l5whup2h/0.juju-log test mode is enabled
unit-test-l5whup2h-0: 13:50:05 ERROR unit.test-l5whup2h/0.juju-log Failed to create openstack server test-l5whup2h-0-15ca92d1d341
Traceback (most recent call last):
  File "/var/lib/juju/agents/unit-test-l5whup2h-0/charm/venv/github_runner_manager/openstack_cloud/openstack_cloud.py", line 227, in launch_instance
    server = conn.create_server(
  File "/var/lib/juju/agents/unit-test-l5whup2h-0/charm/venv/decorator.py", line 232, in fun
    return caller(func, *(extras + args), **kw)
  File "/var/lib/juju/agents/unit-test-l5whup2h-0/charm/venv/openstack/cloud/_utils.py", line 224, in func_wrapper
    return func(*args, **kwargs)
  File "/var/lib/juju/agents/unit-test-l5whup2h-0/charm/venv/openstack/cloud/_compute.py", line 992, in create_server
    server = self.compute.create_server(**kwargs)
  File "/var/lib/juju/agents/unit-test-l5whup2h-0/charm/venv/openstack/compute/v2/_proxy.py", line 727, in create_server
    return self._create(_server.Server, **attrs)
  File "/var/lib/juju/agents/unit-test-l5whup2h-0/charm/venv/openstack/proxy.py", line 643, in _create
    return res.create(self, base_path=base_path)
  File "/var/lib/juju/agents/unit-test-l5whup2h-0/charm/venv/openstack/resource.py", line 1533, in create
    self._translate_response(response, **response_kwargs)
  File "/var/lib/juju/agents/unit-test-l5whup2h-0/charm/venv/openstack/resource.py", line 1285, in _translate_response
    exceptions.raise_from_response(response, error_message=error_message)
  File "/var/lib/juju/agents/unit-test-l5whup2h-0/charm/venv/openstack/exceptions.py", line 247, in raise_from_response
    raise cls(
openstack.exceptions.ForbiddenException: ForbiddenException: 403: Client Error for url: https://nova.ps6.canonical.com:8774/v2.1/servers, Maximum number of ports exceeded
unit-test-l5whup2h-0: 13:50:05 ERROR unit.test-l5whup2h/0.juju-log Failed to spawn a runner.
Traceback (most recent call last):
  File "/var/lib/juju/agents/unit-test-l5whup2h-0/charm/venv/github_runner_manager/openstack_cloud/openstack_cloud.py", line 227, in launch_instance
    server = conn.create_server(
  File "/var/lib/juju/agents/unit-test-l5whup2h-0/charm/venv/decorator.py", line 232, in fun
    return caller(func, *(extras + args), **kw)
  File "/var/lib/juju/agents/unit-test-l5whup2h-0/charm/venv/openstack/cloud/_utils.py", line 224, in func_wrapper
    return func(*args, **kwargs)
  File "/var/lib/juju/agents/unit-test-l5whup2h-0/charm/venv/openstack/cloud/_compute.py", line 992, in create_server
    server = self.compute.create_server(**kwargs)
  File "/var/lib/juju/agents/unit-test-l5whup2h-0/charm/venv/openstack/compute/v2/_proxy.py", line 727, in create_server
    return self._create(_server.Server, **attrs)
  File "/var/lib/juju/agents/unit-test-l5whup2h-0/charm/venv/openstack/proxy.py", line 643, in _create
    return res.create(self, base_path=base_path)
  File "/var/lib/juju/agents/unit-test-l5whup2h-0/charm/venv/openstack/resource.py", line 1533, in create
    self._translate_response(response, **response_kwargs)
  File "/var/lib/juju/agents/unit-test-l5whup2h-0/charm/venv/openstack/resource.py", line 1285, in _translate_response
    exceptions.raise_from_response(response, error_message=error_message)
  File "/var/lib/juju/agents/unit-test-l5whup2h-0/charm/venv/openstack/exceptions.py", line 247, in raise_from_response
    raise cls(
openstack.exceptions.ForbiddenException: ForbiddenException: 403: Client Error for url: https://nova.ps6.canonical.com:8774/v2.1/servers, Maximum number of ports exceeded

The above exception was the direct cause of the following exception:

Traceback (most recent call last):
  File "/var/lib/juju/agents/unit-test-l5whup2h-0/charm/venv/github_runner_manager/openstack_cloud/openstack_runner_manager.py", line 209, in create_runner
    instance = self._openstack_cloud.launch_instance(
  File "/var/lib/juju/agents/unit-test-l5whup2h-0/charm/venv/github_runner_manager/openstack_cloud/openstack_cloud.py", line 138, in exception_handling_wrapper
    return func(*args, **kwargs)
  File "/var/lib/juju/agents/unit-test-l5whup2h-0/charm/venv/github_runner_manager/openstack_cloud/openstack_cloud.py", line 250, in launch_instance
    raise OpenStackError(f"Failed to create openstack server {full_name}") from err
github_runner_manager.errors.OpenStackError: Failed to create openstack server test-l5whup2h-0-15ca92d1d341

The above exception was the direct cause of the following exception:

Traceback (most recent call last):
  File "/var/lib/juju/agents/unit-test-l5whup2h-0/charm/venv/github_runner_manager/manager/runner_manager.py", line 276, in _spawn_runners
    return (RunnerManager._create_runner(create_runner_args_sequence[0]),)
  File "/var/lib/juju/agents/unit-test-l5whup2h-0/charm/venv/github_runner_manager/manager/runner_manager.py", line 404, in _create_runner
    return args.cloud_runner_manager.create_runner(registration_token=args.registration_token)
  File "/var/lib/juju/agents/unit-test-l5whup2h-0/charm/venv/github_runner_manager/openstack_cloud/openstack_runner_manager.py", line 217, in create_runner
    raise RunnerCreateError(f"Failed to create {instance_name} openstack runner") from err
github_runner_manager.errors.RunnerCreateError: Failed to create test-l5whup2h-0-15ca92d1d341 openstack runner
unit-test-l5whup2h-0: 13:50:13 CRITICAL unit.test-l5whup2h/0.juju-log test mode is enabled
unit-test-l5whup2h-0: 13:50:33 ERROR unit.test-l5whup2h/0.juju-log Failed to create openstack server test-l5whup2h-0-a1dc6514aebe
Traceback (most recent call last):
  File "/var/lib/juju/agents/unit-test-l5whup2h-0/charm/venv/github_runner_manager/openstack_cloud/openstack_cloud.py", line 227, in launch_instance
    server = conn.create_server(
  File "/var/lib/juju/agents/unit-test-l5whup2h-0/charm/venv/decorator.py", line 232, in fun
    return caller(func, *(extras + args), **kw)
  File "/var/lib/juju/agents/unit-test-l5whup2h-0/charm/venv/openstack/cloud/_utils.py", line 224, in func_wrapper
    return func(*args, **kwargs)
  File "/var/lib/juju/agents/unit-test-l5whup2h-0/charm/venv/openstack/cloud/_compute.py", line 992, in create_server
    server = self.compute.create_server(**kwargs)
  File "/var/lib/juju/agents/unit-test-l5whup2h-0/charm/venv/openstack/compute/v2/_proxy.py", line 727, in create_server
    return self._create(_server.Server, **attrs)
  File "/var/lib/juju/agents/unit-test-l5whup2h-0/charm/venv/openstack/proxy.py", line 643, in _create
    return res.create(self, base_path=base_path)
  File "/var/lib/juju/agents/unit-test-l5whup2h-0/charm/venv/openstack/resource.py", line 1533, in create
    self._translate_response(response, **response_kwargs)
  File "/var/lib/juju/agents/unit-test-l5whup2h-0/charm/venv/openstack/resource.py", line 1285, in _translate_response
    exceptions.raise_from_response(response, error_message=error_message)
  File "/var/lib/juju/agents/unit-test-l5whup2h-0/charm/venv/openstack/exceptions.py", line 247, in raise_from_response
    raise cls(
openstack.exceptions.ForbiddenException: ForbiddenException: 403: Client Error for url: https://nova.ps6.canonical.com:8774/v2.1/servers, Maximum number of ports exceeded
unit-test-l5whup2h-0: 13:50:33 ERROR unit.test-l5whup2h/0.juju-log Failed to spawn a runner.
Traceback (most recent call last):
  File "/var/lib/juju/agents/unit-test-l5whup2h-0/charm/venv/github_runner_manager/openstack_cloud/openstack_cloud.py", line 227, in launch_instance
    server = conn.create_server(
  File "/var/lib/juju/agents/unit-test-l5whup2h-0/charm/venv/decorator.py", line 232, in fun
    return caller(func, *(extras + args), **kw)
  File "/var/lib/juju/agents/unit-test-l5whup2h-0/charm/venv/openstack/cloud/_utils.py", line 224, in func_wrapper
    return func(*args, **kwargs)
  File "/var/lib/juju/agents/unit-test-l5whup2h-0/charm/venv/openstack/cloud/_compute.py", line 992, in create_server
    server = self.compute.create_server(**kwargs)
  File "/var/lib/juju/agents/unit-test-l5whup2h-0/charm/venv/openstack/compute/v2/_proxy.py", line 727, in create_server
    return self._create(_server.Server, **attrs)
  File "/var/lib/juju/agents/unit-test-l5whup2h-0/charm/venv/openstack/proxy.py", line 643, in _create
    return res.create(self, base_path=base_path)
  File "/var/lib/juju/agents/unit-test-l5whup2h-0/charm/venv/openstack/resource.py", line 1533, in create
    self._translate_response(response, **response_kwargs)
  File "/var/lib/juju/agents/unit-test-l5whup2h-0/charm/venv/openstack/resource.py", line 1285, in _translate_response
    exceptions.raise_from_response(response, error_message=error_message)
  File "/var/lib/juju/agents/unit-test-l5whup2h-0/charm/venv/openstack/exceptions.py", line 247, in raise_from_response
    raise cls(
openstack.exceptions.ForbiddenException: ForbiddenException: 403: Client Error for url: https://nova.ps6.canonical.com:8774/v2.1/servers, Maximum number of ports exceeded

The above exception was the direct cause of the following exception:

Traceback (most recent call last):
  File "/var/lib/juju/agents/unit-test-l5whup2h-0/charm/venv/github_runner_manager/openstack_cloud/openstack_runner_manager.py", line 209, in create_runner
    instance = self._openstack_cloud.launch_instance(
  File "/var/lib/juju/agents/unit-test-l5whup2h-0/charm/venv/github_runner_manager/openstack_cloud/openstack_cloud.py", line 138, in exception_handling_wrapper
    return func(*args, **kwargs)
  File "/var/lib/juju/agents/unit-test-l5whup2h-0/charm/venv/github_runner_manager/openstack_cloud/openstack_cloud.py", line 250, in launch_instance
    raise OpenStackError(f"Failed to create openstack server {full_name}") from err
github_runner_manager.errors.OpenStackError: Failed to create openstack server test-l5whup2h-0-a1dc6514aebe

The above exception was the direct cause of the following exception:

Traceback (most recent call last):
  File "/var/lib/juju/agents/unit-test-l5whup2h-0/charm/venv/github_runner_manager/manager/runner_manager.py", line 276, in _spawn_runners
    return (RunnerManager._create_runner(create_runner_args_sequence[0]),)
  File "/var/lib/juju/agents/unit-test-l5whup2h-0/charm/venv/github_runner_manager/manager/runner_manager.py", line 404, in _create_runner
    return args.cloud_runner_manager.create_runner(registration_token=args.registration_token)
  File "/var/lib/juju/agents/unit-test-l5whup2h-0/charm/venv/github_runner_manager/openstack_cloud/openstack_runner_manager.py", line 217, in create_runner
    raise RunnerCreateError(f"Failed to create {instance_name} openstack runner") from err
github_runner_manager.errors.RunnerCreateError: Failed to create test-l5whup2h-0-a1dc6514aebe openstack runner

INFO     pytest_operator.plugin:plugin.py:1017 Forgetting model main...