INFO     root:charm_metrics.py:127 Loop device None not found
INFO     juju.model:__init__.py:3254 Waiting for model:
  test-ydky3p5v/0 [executing] active:
INFO     juju.model:__init__.py:3254 Waiting for model:
  test-ydky3p5v/0 [executing] active: 
INFO     juju.model:__init__.py:3254 Waiting for model:
  test-ydky3p5v/0 [executing] maintenance: Reconciling runners
INFO     juju.model:__init__.py:3254 Waiting for model:
  test-ydky3p5v/0 [executing] maintenance: Reconciling runners
INFO     juju.model:__init__.py:3254 Waiting for model:
  test-ydky3p5v/0 [executing] maintenance: Reconciling runners
INFO     tests.integration.helpers.common:common.py:525 Wait for condition not met, sleeping 30
INFO     tests.integration.helpers.openstack:openstack.py:104 [TEST SETUP] Run command pkill -9 run.sh on test-ydky3p5v-0-6a234bbdfebd
WARNING  tests.integration.helpers.openstack:openstack.py:106 dict_values([[{'version': 4, 'addr': '10.145.193.247', 'OS-EXT-IPS:type': 'fixed', 'OS-EXT-IPS-MAC:mac_addr': 'fa:16:3e:85:8b:16'}]])
WARNING  root:openstack.py:123 ssh_cmd: su - ubuntu -c 'ssh -i /home/runner-manager/.ssh/test-ydky3p5v-0-6a234bbdfebd.key -o "StrictHostKeyChecking no" ubuntu@10.145.193.247 pkill -9 run.sh'
INFO     root:charm_metrics.py:248 Runner test-ydky3p5v-0-6a234bbdfebd status: online
INFO     root:charm_metrics.py:250 Runner still marked as online, waiting for it to be marked offline
INFO     juju.model:__init__.py:3254 Waiting for model:
  test-ydky3p5v/0 [executing] active: 
INFO     root:common.py:609 File content of /var/log/github-runner-metrics.log: {"timestamp": 1734849584.0705051, "event": "reconciliation", "flavor": "test-ydky3p5v", "crashed_runners": 0, "idle_runners": 0, "active_runners": 0, "expected_runners": 0, "duration": 10.454528331756592}
{"timestamp": 1734849595.4731085, "event": "reconciliation", "flavor": "test-ydky3p5v", "crashed_runners": 0, "idle_runners": 0, "active_runners": 0, "expected_runners": 0, "duration": 10.356623888015747}
{"timestamp": 1734849929.41996, "event": "reconciliation", "flavor": "test-ydky3p5v", "crashed_runners": 0, "idle_runners": 0, "active_runners": 0, "expected_runners": 1, "duration": 315.8863196372986}
{"timestamp": 1734850026.669549, "event": "reconciliation", "flavor": "test-ydky3p5v", "crashed_runners": 0, "idle_runners": 1, "active_runners": 0, "expected_runners": 1, "duration": 96.20227289199829}
{"timestamp": 1734849997.0, "event": "runner_installed", "flavor": "test-ydky3p5v", "duration": 58.31001424789429}
{"timestamp": 1734850052.0, "event": "runner_start", "flavor": "test-ydky3p5v", "workflow": "Workflow Dispatch Crash Tests", "repo": "canonical/github-runner-operator", "github_event": "workflow_dispatch", "idle": 55.0, "queue_duration": 8.0}
{"timestamp": 1734850090.0, "event": "runner_stop", "flavor": "test-ydky3p5v", "workflow": "Workflow Dispatch Crash Tests", "repo": "canonical/github-runner-operator", "github_event": "workflow_dispatch", "status": "abnormal", "status_info": {"code": 137}, "job_duration": 38.0, "job_conclusion": "cancelled"}
{"timestamp": 1734850188.2905612, "event": "reconciliation", "flavor": "test-ydky3p5v", "crashed_runners": 0, "idle_runners": 0, "active_runners": 0, "expected_runners": 0, "duration": 30.38235354423523}
{"timestamp": 1734850202.1429598, "event": "reconciliation", "flavor": "test-ydky3p5v", "crashed_runners": 0, "idle_runners": 0, "active_runners": 0, "expected_runners": 0, "duration": 12.84839391708374}
INFO     pytest_operator.plugin:plugin.py:929 Model status:

Model                            Controller  Cloud/Region         Version  SLA          Timestamp
test-charm-metrics-failure-z4j4  lxd         localhost/localhost  3.6.1    unsupported  06:50:20Z

App                          Version  Status  Scale  Charm                        Channel      Rev  Exposed  Message
github-runner-image-builder           active      1  github-runner-image-builder  latest/edge    2  no       
test-ydky3p5v                         active      1  github-runner                               0  yes      

Unit                            Workload  Agent  Machine  Public address  Ports     Message
github-runner-image-builder/0*  active    idle   0        10.212.208.97             
test-ydky3p5v/0*                active    idle   1        10.212.208.216  8080/tcp  

Machine  State    Address         Inst id        Base          AZ  Message
0        started  10.212.208.97   juju-2dc16c-0  ubuntu@22.04      Running
1        started  10.212.208.216  juju-2dc16c-1  ubuntu@22.04      Running

INFO     pytest_operator.plugin:plugin.py:935 Juju error logs:

machine-0: 06:25:08 ERROR juju.worker.dependency "kvm-container-provisioner" manifold worker returned unexpected error: container types not yet available
machine-0: 06:25:08 ERROR juju.worker.dependency "lxd-container-provisioner" manifold worker returned unexpected error: container types not yet available
unit-github-runner-image-builder-0: 06:25:08 ERROR juju.worker.meterstatus error running "meter-status-changed": charm missing from disk
machine-1: 06:28:13 ERROR juju.worker.dependency "kvm-container-provisioner" manifold worker returned unexpected error: container types not yet available
machine-1: 06:28:13 ERROR juju.worker.dependency "lxd-container-provisioner" manifold worker returned unexpected error: container types not yet available
unit-test-ydky3p5v-0: 06:28:13 ERROR juju.worker.meterstatus error running "meter-status-changed": charm missing from disk
unit-test-ydky3p5v-0: 06:28:26 CRITICAL unit.test-ydky3p5v/0.juju-log test mode is enabled
unit-test-ydky3p5v-0: 06:28:27 CRITICAL unit.test-ydky3p5v/0.juju-log test mode is enabled
unit-test-ydky3p5v-0: 06:28:31 CRITICAL unit.test-ydky3p5v/0.juju-log image:0: test mode is enabled
unit-test-ydky3p5v-0: 06:28:32 CRITICAL unit.test-ydky3p5v/0.juju-log test mode is enabled
unit-test-ydky3p5v-0: 06:28:33 CRITICAL unit.test-ydky3p5v/0.juju-log test mode is enabled
unit-test-ydky3p5v-0: 06:28:34 CRITICAL unit.test-ydky3p5v/0.juju-log test mode is enabled
unit-test-ydky3p5v-0: 06:28:35 CRITICAL unit.test-ydky3p5v/0.juju-log test mode is enabled
unit-test-ydky3p5v-0: 06:28:36 CRITICAL unit.test-ydky3p5v/0.juju-log image:0: test mode is enabled
unit-test-ydky3p5v-0: 06:28:37 CRITICAL unit.test-ydky3p5v/0.juju-log image:0: test mode is enabled
unit-test-ydky3p5v-0: 06:29:22 CRITICAL unit.test-ydky3p5v/0.juju-log test mode is enabled
unit-test-ydky3p5v-0: 06:29:23 CRITICAL unit.test-ydky3p5v/0.juju-log test mode is enabled
unit-test-ydky3p5v-0: 06:29:38 CRITICAL unit.test-ydky3p5v/0.juju-log test mode is enabled
unit-test-ydky3p5v-0: 06:30:05 CRITICAL unit.test-ydky3p5v/0.juju-log test mode is enabled
unit-test-ydky3p5v-0: 06:30:20 CRITICAL unit.test-ydky3p5v/0.juju-log test mode is enabled
unit-test-ydky3p5v-0: 06:30:57 CRITICAL unit.test-ydky3p5v/0.juju-log test mode is enabled
unit-test-ydky3p5v-0: 06:30:58 CRITICAL unit.test-ydky3p5v/0.juju-log test mode is enabled
unit-test-ydky3p5v-0: 06:33:05 CRITICAL unit.test-ydky3p5v/0.juju-log test mode is enabled
unit-test-ydky3p5v-0: 06:33:23 CRITICAL unit.test-ydky3p5v/0.juju-log test mode is enabled
unit-test-ydky3p5v-0: 06:34:58 CRITICAL unit.test-ydky3p5v/0.juju-log image:0: test mode is enabled
unit-test-ydky3p5v-0: 06:35:14 ERROR unit.test-ydky3p5v/0.juju-log image:0: Health check failed due to unable to find keyfile for test-ydky3p5v-0-814c31b4ba65
Traceback (most recent call last):
  File "/var/lib/juju/agents/unit-test-ydky3p5v-0/charm/venv/github_runner_manager/openstack_cloud/openstack_runner_manager.py", line 590, in _check_state_and_flush
    ssh_conn = self._openstack_cloud.get_ssh_connection(instance)
  File "/var/lib/juju/agents/unit-test-ydky3p5v-0/charm/venv/github_runner_manager/openstack_cloud/openstack_cloud.py", line 138, in exception_handling_wrapper
    return func(*args, **kwargs)
  File "/var/lib/juju/agents/unit-test-ydky3p5v-0/charm/venv/github_runner_manager/openstack_cloud/openstack_cloud.py", line 324, in get_ssh_connection
    raise KeyfileError(
github_runner_manager.errors.KeyfileError: Missing keyfile for server: test-ydky3p5v-0-814c31b4ba65, key path: /home/runner-manager/.ssh/test-ydky3p5v-0-814c31b4ba65.key
unit-test-ydky3p5v-0: 06:35:17 ERROR unit.test-ydky3p5v/0.juju-log image:0: Unable to get SSH connection for instance test-ydky3p5v-0-814c31b4ba65, marking as unhealthy.
Traceback (most recent call last):
  File "/var/lib/juju/agents/unit-test-ydky3p5v-0/charm/venv/github_runner_manager/openstack_cloud/health_checks.py", line 130, in _get_ssh_connection
    ssh_conn = openstack_cloud.get_ssh_connection(instance)
  File "/var/lib/juju/agents/unit-test-ydky3p5v-0/charm/venv/github_runner_manager/openstack_cloud/openstack_cloud.py", line 138, in exception_handling_wrapper
    return func(*args, **kwargs)
  File "/var/lib/juju/agents/unit-test-ydky3p5v-0/charm/venv/github_runner_manager/openstack_cloud/openstack_cloud.py", line 324, in get_ssh_connection
    raise KeyfileError(
github_runner_manager.errors.KeyfileError: Missing keyfile for server: test-ydky3p5v-0-814c31b4ba65, key path: /home/runner-manager/.ssh/test-ydky3p5v-0-814c31b4ba65.key

The above exception was the direct cause of the following exception:

Traceback (most recent call last):
  File "/var/lib/juju/agents/unit-test-ydky3p5v-0/charm/venv/github_runner_manager/openstack_cloud/health_checks.py", line 49, in check_runner
    ssh_conn = _get_ssh_connection(openstack_cloud=openstack_cloud, instance=instance)
  File "/var/lib/juju/agents/unit-test-ydky3p5v-0/charm/venv/github_runner_manager/utilities.py", line 77, in fn_with_retry
    return func(*args, **kwargs)
  File "/var/lib/juju/agents/unit-test-ydky3p5v-0/charm/venv/github_runner_manager/openstack_cloud/health_checks.py", line 133, in _get_ssh_connection
    raise _SSHError(f"Unable to get SSH connection to {instance.server_name}") from exc
github_runner_manager.openstack_cloud.health_checks._SSHError: Unable to get SSH connection to test-ydky3p5v-0-814c31b4ba65
unit-test-ydky3p5v-0: 06:35:17 ERROR unit.test-ydky3p5v/0.juju-log image:0: Failed to get SSH connection while removing test-ydky3p5v-0-814c31b4ba65
Traceback (most recent call last):
  File "/var/lib/juju/agents/unit-test-ydky3p5v-0/charm/venv/github_runner_manager/openstack_cloud/openstack_runner_manager.py", line 441, in _delete_runner
    ssh_conn = self._openstack_cloud.get_ssh_connection(instance)
  File "/var/lib/juju/agents/unit-test-ydky3p5v-0/charm/venv/github_runner_manager/openstack_cloud/openstack_cloud.py", line 138, in exception_handling_wrapper
    return func(*args, **kwargs)
  File "/var/lib/juju/agents/unit-test-ydky3p5v-0/charm/venv/github_runner_manager/openstack_cloud/openstack_cloud.py", line 324, in get_ssh_connection
    raise KeyfileError(
github_runner_manager.errors.KeyfileError: Missing keyfile for server: test-ydky3p5v-0-814c31b4ba65, key path: /home/runner-manager/.ssh/test-ydky3p5v-0-814c31b4ba65.key
unit-test-ydky3p5v-0: 06:38:14 CRITICAL unit.test-ydky3p5v/0.juju-log test mode is enabled
unit-test-ydky3p5v-0: 06:38:41 ERROR unit.test-ydky3p5v/0.juju-log pre-job-metrics.json not found for runner test-ydky3p5v-0-4801f14b1864
Traceback (most recent call last):
  File "/var/lib/juju/agents/unit-test-ydky3p5v-0/charm/venv/github_runner_manager/metrics/runner.py", line 557, in _extract_file_from_storage
    file_content = metrics_storage.path.joinpath(filename).read_text(encoding="utf-8")
  File "/usr/lib/python3.10/pathlib.py", line 1134, in read_text
    with self.open(mode='r', encoding=encoding, errors=errors) as f:
  File "/usr/lib/python3.10/pathlib.py", line 1119, in open
    return self._accessor.open(self, mode, buffering, encoding, errors,
FileNotFoundError: [Errno 2] No such file or directory: '/home/runner-manager/runner-fs/test-ydky3p5v-0-4801f14b1864/pre-job-metrics.json'
unit-test-ydky3p5v-0: 06:38:41 ERROR unit.test-ydky3p5v/0.juju-log Pre-job metrics for runner test-ydky3p5v-0-4801f14b1864 not found, stop extracting post-jobs metrics.
unit-test-ydky3p5v-0: 06:38:44 ERROR unit.test-ydky3p5v/0.juju-log Unable to get SSH connection for instance test-ydky3p5v-0-4801f14b1864, marking as unhealthy.
Traceback (most recent call last):
  File "/var/lib/juju/agents/unit-test-ydky3p5v-0/charm/venv/github_runner_manager/openstack_cloud/health_checks.py", line 130, in _get_ssh_connection
    ssh_conn = openstack_cloud.get_ssh_connection(instance)
  File "/var/lib/juju/agents/unit-test-ydky3p5v-0/charm/venv/github_runner_manager/openstack_cloud/openstack_cloud.py", line 138, in exception_handling_wrapper
    return func(*args, **kwargs)
  File "/var/lib/juju/agents/unit-test-ydky3p5v-0/charm/venv/github_runner_manager/openstack_cloud/openstack_cloud.py", line 324, in get_ssh_connection
    raise KeyfileError(
github_runner_manager.errors.KeyfileError: Missing keyfile for server: test-ydky3p5v-0-4801f14b1864, key path: /home/runner-manager/.ssh/test-ydky3p5v-0-4801f14b1864.key

The above exception was the direct cause of the following exception:

Traceback (most recent call last):
  File "/var/lib/juju/agents/unit-test-ydky3p5v-0/charm/venv/github_runner_manager/openstack_cloud/health_checks.py", line 49, in check_runner
    ssh_conn = _get_ssh_connection(openstack_cloud=openstack_cloud, instance=instance)
  File "/var/lib/juju/agents/unit-test-ydky3p5v-0/charm/venv/github_runner_manager/utilities.py", line 77, in fn_with_retry
    return func(*args, **kwargs)
  File "/var/lib/juju/agents/unit-test-ydky3p5v-0/charm/venv/github_runner_manager/openstack_cloud/health_checks.py", line 133, in _get_ssh_connection
    raise _SSHError(f"Unable to get SSH connection to {instance.server_name}") from exc
github_runner_manager.openstack_cloud.health_checks._SSHError: Unable to get SSH connection to test-ydky3p5v-0-4801f14b1864
unit-test-ydky3p5v-0: 06:38:45 CRITICAL unit.test-ydky3p5v/0.juju-log test mode is enabled
unit-test-ydky3p5v-0: 06:38:47 CRITICAL unit.test-ydky3p5v/0.juju-log test mode is enabled
unit-test-ydky3p5v-0: 06:38:51 ERROR unit.test-ydky3p5v/0.juju-log Unable to get SSH connection for instance test-ydky3p5v-0-4801f14b1864, marking as unhealthy.
Traceback (most recent call last):
  File "/var/lib/juju/agents/unit-test-ydky3p5v-0/charm/venv/github_runner_manager/openstack_cloud/health_checks.py", line 130, in _get_ssh_connection
    ssh_conn = openstack_cloud.get_ssh_connection(instance)
  File "/var/lib/juju/agents/unit-test-ydky3p5v-0/charm/venv/github_runner_manager/openstack_cloud/openstack_cloud.py", line 138, in exception_handling_wrapper
    return func(*args, **kwargs)
  File "/var/lib/juju/agents/unit-test-ydky3p5v-0/charm/venv/github_runner_manager/openstack_cloud/openstack_cloud.py", line 324, in get_ssh_connection
    raise KeyfileError(
github_runner_manager.errors.KeyfileError: Missing keyfile for server: test-ydky3p5v-0-4801f14b1864, key path: /home/runner-manager/.ssh/test-ydky3p5v-0-4801f14b1864.key

The above exception was the direct cause of the following exception:

Traceback (most recent call last):
  File "/var/lib/juju/agents/unit-test-ydky3p5v-0/charm/venv/github_runner_manager/openstack_cloud/health_checks.py", line 49, in check_runner
    ssh_conn = _get_ssh_connection(openstack_cloud=openstack_cloud, instance=instance)
  File "/var/lib/juju/agents/unit-test-ydky3p5v-0/charm/venv/github_runner_manager/utilities.py", line 77, in fn_with_retry
    return func(*args, **kwargs)
  File "/var/lib/juju/agents/unit-test-ydky3p5v-0/charm/venv/github_runner_manager/openstack_cloud/health_checks.py", line 133, in _get_ssh_connection
    raise _SSHError(f"Unable to get SSH connection to {instance.server_name}") from exc
github_runner_manager.openstack_cloud.health_checks._SSHError: Unable to get SSH connection to test-ydky3p5v-0-4801f14b1864
unit-test-ydky3p5v-0: 06:38:51 ERROR unit.test-ydky3p5v/0.juju-log Failed to get SSH connection while removing test-ydky3p5v-0-4801f14b1864
Traceback (most recent call last):
  File "/var/lib/juju/agents/unit-test-ydky3p5v-0/charm/venv/github_runner_manager/openstack_cloud/openstack_runner_manager.py", line 441, in _delete_runner
    ssh_conn = self._openstack_cloud.get_ssh_connection(instance)
  File "/var/lib/juju/agents/unit-test-ydky3p5v-0/charm/venv/github_runner_manager/openstack_cloud/openstack_cloud.py", line 138, in exception_handling_wrapper
    return func(*args, **kwargs)
  File "/var/lib/juju/agents/unit-test-ydky3p5v-0/charm/venv/github_runner_manager/openstack_cloud/openstack_cloud.py", line 324, in get_ssh_connection
    raise KeyfileError(
github_runner_manager.errors.KeyfileError: Missing keyfile for server: test-ydky3p5v-0-4801f14b1864, key path: /home/runner-manager/.ssh/test-ydky3p5v-0-4801f14b1864.key
unit-test-ydky3p5v-0: 06:38:58 ERROR unit.test-ydky3p5v/0.juju-log Unable to get SSH connection for instance test-ydky3p5v-0-4801f14b1864, marking as unhealthy.
Traceback (most recent call last):
  File "/var/lib/juju/agents/unit-test-ydky3p5v-0/charm/venv/github_runner_manager/openstack_cloud/health_checks.py", line 130, in _get_ssh_connection
    ssh_conn = openstack_cloud.get_ssh_connection(instance)
  File "/var/lib/juju/agents/unit-test-ydky3p5v-0/charm/venv/github_runner_manager/openstack_cloud/openstack_cloud.py", line 138, in exception_handling_wrapper
    return func(*args, **kwargs)
  File "/var/lib/juju/agents/unit-test-ydky3p5v-0/charm/venv/github_runner_manager/openstack_cloud/openstack_cloud.py", line 324, in get_ssh_connection
    raise KeyfileError(
github_runner_manager.errors.KeyfileError: Missing keyfile for server: test-ydky3p5v-0-4801f14b1864, key path: /home/runner-manager/.ssh/test-ydky3p5v-0-4801f14b1864.key

The above exception was the direct cause of the following exception:

Traceback (most recent call last):
  File "/var/lib/juju/agents/unit-test-ydky3p5v-0/charm/venv/github_runner_manager/openstack_cloud/health_checks.py", line 49, in check_runner
    ssh_conn = _get_ssh_connection(openstack_cloud=openstack_cloud, instance=instance)
  File "/var/lib/juju/agents/unit-test-ydky3p5v-0/charm/venv/github_runner_manager/utilities.py", line 77, in fn_with_retry
    return func(*args, **kwargs)
  File "/var/lib/juju/agents/unit-test-ydky3p5v-0/charm/venv/github_runner_manager/openstack_cloud/health_checks.py", line 133, in _get_ssh_connection
    raise _SSHError(f"Unable to get SSH connection to {instance.server_name}") from exc
github_runner_manager.openstack_cloud.health_checks._SSHError: Unable to get SSH connection to test-ydky3p5v-0-4801f14b1864
unit-test-ydky3p5v-0: 06:39:02 ERROR unit.test-ydky3p5v/0.juju-log Unable to get SSH connection for instance test-ydky3p5v-0-4801f14b1864, marking as unhealthy.
Traceback (most recent call last):
  File "/var/lib/juju/agents/unit-test-ydky3p5v-0/charm/venv/github_runner_manager/openstack_cloud/health_checks.py", line 130, in _get_ssh_connection
    ssh_conn = openstack_cloud.get_ssh_connection(instance)
  File "/var/lib/juju/agents/unit-test-ydky3p5v-0/charm/venv/github_runner_manager/openstack_cloud/openstack_cloud.py", line 138, in exception_handling_wrapper
    return func(*args, **kwargs)
  File "/var/lib/juju/agents/unit-test-ydky3p5v-0/charm/venv/github_runner_manager/openstack_cloud/openstack_cloud.py", line 324, in get_ssh_connection
    raise KeyfileError(
github_runner_manager.errors.KeyfileError: Missing keyfile for server: test-ydky3p5v-0-4801f14b1864, key path: /home/runner-manager/.ssh/test-ydky3p5v-0-4801f14b1864.key

The above exception was the direct cause of the following exception:

Traceback (most recent call last):
  File "/var/lib/juju/agents/unit-test-ydky3p5v-0/charm/venv/github_runner_manager/openstack_cloud/health_checks.py", line 49, in check_runner
    ssh_conn = _get_ssh_connection(openstack_cloud=openstack_cloud, instance=instance)
  File "/var/lib/juju/agents/unit-test-ydky3p5v-0/charm/venv/github_runner_manager/utilities.py", line 77, in fn_with_retry
    return func(*args, **kwargs)
  File "/var/lib/juju/agents/unit-test-ydky3p5v-0/charm/venv/github_runner_manager/openstack_cloud/health_checks.py", line 133, in _get_ssh_connection
    raise _SSHError(f"Unable to get SSH connection to {instance.server_name}") from exc
github_runner_manager.openstack_cloud.health_checks._SSHError: Unable to get SSH connection to test-ydky3p5v-0-4801f14b1864
unit-test-ydky3p5v-0: 06:39:04 ERROR unit.test-ydky3p5v/0.juju-log Failed to get SSH connection while removing test-ydky3p5v-0-4801f14b1864
Traceback (most recent call last):
  File "/var/lib/juju/agents/unit-test-ydky3p5v-0/charm/venv/github_runner_manager/openstack_cloud/openstack_runner_manager.py", line 441, in _delete_runner
    ssh_conn = self._openstack_cloud.get_ssh_connection(instance)
  File "/var/lib/juju/agents/unit-test-ydky3p5v-0/charm/venv/github_runner_manager/openstack_cloud/openstack_cloud.py", line 138, in exception_handling_wrapper
    return func(*args, **kwargs)
  File "/var/lib/juju/agents/unit-test-ydky3p5v-0/charm/venv/github_runner_manager/openstack_cloud/openstack_cloud.py", line 324, in get_ssh_connection
    raise KeyfileError(
github_runner_manager.errors.KeyfileError: Missing keyfile for server: test-ydky3p5v-0-4801f14b1864, key path: /home/runner-manager/.ssh/test-ydky3p5v-0-4801f14b1864.key
unit-test-ydky3p5v-0: 06:39:10 ERROR unit.test-ydky3p5v/0.juju-log Unable to get SSH connection for instance test-ydky3p5v-0-4801f14b1864, marking as unhealthy.
Traceback (most recent call last):
  File "/var/lib/juju/agents/unit-test-ydky3p5v-0/charm/venv/github_runner_manager/openstack_cloud/health_checks.py", line 130, in _get_ssh_connection
    ssh_conn = openstack_cloud.get_ssh_connection(instance)
  File "/var/lib/juju/agents/unit-test-ydky3p5v-0/charm/venv/github_runner_manager/openstack_cloud/openstack_cloud.py", line 138, in exception_handling_wrapper
    return func(*args, **kwargs)
  File "/var/lib/juju/agents/unit-test-ydky3p5v-0/charm/venv/github_runner_manager/openstack_cloud/openstack_cloud.py", line 324, in get_ssh_connection
    raise KeyfileError(
github_runner_manager.errors.KeyfileError: Missing keyfile for server: test-ydky3p5v-0-4801f14b1864, key path: /home/runner-manager/.ssh/test-ydky3p5v-0-4801f14b1864.key

The above exception was the direct cause of the following exception:

Traceback (most recent call last):
  File "/var/lib/juju/agents/unit-test-ydky3p5v-0/charm/venv/github_runner_manager/openstack_cloud/health_checks.py", line 49, in check_runner
    ssh_conn = _get_ssh_connection(openstack_cloud=openstack_cloud, instance=instance)
  File "/var/lib/juju/agents/unit-test-ydky3p5v-0/charm/venv/github_runner_manager/utilities.py", line 77, in fn_with_retry
    return func(*args, **kwargs)
  File "/var/lib/juju/agents/unit-test-ydky3p5v-0/charm/venv/github_runner_manager/openstack_cloud/health_checks.py", line 133, in _get_ssh_connection
    raise _SSHError(f"Unable to get SSH connection to {instance.server_name}") from exc
github_runner_manager.openstack_cloud.health_checks._SSHError: Unable to get SSH connection to test-ydky3p5v-0-4801f14b1864
unit-test-ydky3p5v-0: 06:39:32 CRITICAL unit.test-ydky3p5v/0.juju-log test mode is enabled
unit-test-ydky3p5v-0: 06:39:33 CRITICAL unit.test-ydky3p5v/0.juju-log test mode is enabled
unit-test-ydky3p5v-0: 06:39:45 CRITICAL unit.test-ydky3p5v/0.juju-log test mode is enabled
unit-test-ydky3p5v-0: 06:40:12 CRITICAL unit.test-ydky3p5v/0.juju-log test mode is enabled
unit-test-ydky3p5v-0: 06:40:13 CRITICAL unit.test-ydky3p5v/0.juju-log test mode is enabled
unit-test-ydky3p5v-0: 06:45:24 ERROR unit.test-ydky3p5v/0.juju-log Timeout creating openstack server test-ydky3p5v-0-2723c1cbc900
Traceback (most recent call last):
  File "/var/lib/juju/agents/unit-test-ydky3p5v-0/charm/venv/github_runner_manager/openstack_cloud/openstack_cloud.py", line 227, in launch_instance
    server = conn.create_server(
  File "/var/lib/juju/agents/unit-test-ydky3p5v-0/charm/venv/decorator.py", line 232, in fun
    return caller(func, *(extras + args), **kw)
  File "/var/lib/juju/agents/unit-test-ydky3p5v-0/charm/venv/openstack/cloud/_utils.py", line 224, in func_wrapper
    return func(*args, **kwargs)
  File "/var/lib/juju/agents/unit-test-ydky3p5v-0/charm/venv/openstack/cloud/_compute.py", line 1021, in create_server
    server = self.wait_for_server(
  File "/var/lib/juju/agents/unit-test-ydky3p5v-0/charm/venv/openstack/cloud/_compute.py", line 1159, in wait_for_server
    raise exceptions.ResourceTimeout(timeout_message)
openstack.exceptions.ResourceTimeout: Timeout waiting for the server to come up.
unit-test-ydky3p5v-0: 06:45:26 ERROR unit.test-ydky3p5v/0.juju-log Failed to spawn a runner.
Traceback (most recent call last):
  File "/var/lib/juju/agents/unit-test-ydky3p5v-0/charm/venv/github_runner_manager/openstack_cloud/openstack_cloud.py", line 227, in launch_instance
    server = conn.create_server(
  File "/var/lib/juju/agents/unit-test-ydky3p5v-0/charm/venv/decorator.py", line 232, in fun
    return caller(func, *(extras + args), **kw)
  File "/var/lib/juju/agents/unit-test-ydky3p5v-0/charm/venv/openstack/cloud/_utils.py", line 224, in func_wrapper
    return func(*args, **kwargs)
  File "/var/lib/juju/agents/unit-test-ydky3p5v-0/charm/venv/openstack/cloud/_compute.py", line 1021, in create_server
    server = self.wait_for_server(
  File "/var/lib/juju/agents/unit-test-ydky3p5v-0/charm/venv/openstack/cloud/_compute.py", line 1159, in wait_for_server
    raise exceptions.ResourceTimeout(timeout_message)
openstack.exceptions.ResourceTimeout: Timeout waiting for the server to come up.

The above exception was the direct cause of the following exception:

Traceback (most recent call last):
  File "/var/lib/juju/agents/unit-test-ydky3p5v-0/charm/venv/github_runner_manager/openstack_cloud/openstack_runner_manager.py", line 209, in create_runner
    instance = self._openstack_cloud.launch_instance(
  File "/var/lib/juju/agents/unit-test-ydky3p5v-0/charm/venv/github_runner_manager/openstack_cloud/openstack_cloud.py", line 138, in exception_handling_wrapper
    return func(*args, **kwargs)
  File "/var/lib/juju/agents/unit-test-ydky3p5v-0/charm/venv/github_runner_manager/openstack_cloud/openstack_cloud.py", line 246, in launch_instance
    raise OpenStackError(f"Timeout creating openstack server {full_name}") from err
github_runner_manager.errors.OpenStackError: Timeout creating openstack server test-ydky3p5v-0-2723c1cbc900

The above exception was the direct cause of the following exception:

Traceback (most recent call last):
  File "/var/lib/juju/agents/unit-test-ydky3p5v-0/charm/venv/github_runner_manager/manager/runner_manager.py", line 276, in _spawn_runners
    return (RunnerManager._create_runner(create_runner_args_sequence[0]),)
  File "/var/lib/juju/agents/unit-test-ydky3p5v-0/charm/venv/github_runner_manager/manager/runner_manager.py", line 404, in _create_runner
    return args.cloud_runner_manager.create_runner(registration_token=args.registration_token)
  File "/var/lib/juju/agents/unit-test-ydky3p5v-0/charm/venv/github_runner_manager/openstack_cloud/openstack_runner_manager.py", line 217, in create_runner
    raise RunnerCreateError(f"Failed to create {instance_name} openstack runner") from err
github_runner_manager.errors.RunnerCreateError: Failed to create test-ydky3p5v-0-2723c1cbc900 openstack runner
unit-test-ydky3p5v-0: 06:45:30 CRITICAL unit.test-ydky3p5v/0.juju-log test mode is enabled
unit-test-ydky3p5v-0: 06:47:07 CRITICAL unit.test-ydky3p5v/0.juju-log test mode is enabled
unit-test-ydky3p5v-0: 06:47:22 CRITICAL unit.test-ydky3p5v/0.juju-log test mode is enabled
unit-test-ydky3p5v-0: 06:49:16 CRITICAL unit.test-ydky3p5v/0.juju-log test mode is enabled
unit-test-ydky3p5v-0: 06:49:17 CRITICAL unit.test-ydky3p5v/0.juju-log test mode is enabled
unit-test-ydky3p5v-0: 06:49:30 ERROR unit.test-ydky3p5v/0.juju-log runner-installed.timestamp not found for runner test-ydky3p5v-0-2723c1cbc900
Traceback (most recent call last):
  File "/var/lib/juju/agents/unit-test-ydky3p5v-0/charm/venv/github_runner_manager/metrics/runner.py", line 557, in _extract_file_from_storage
    file_content = metrics_storage.path.joinpath(filename).read_text(encoding="utf-8")
  File "/usr/lib/python3.10/pathlib.py", line 1134, in read_text
    with self.open(mode='r', encoding=encoding, errors=errors) as f:
  File "/usr/lib/python3.10/pathlib.py", line 1119, in open
    return self._accessor.open(self, mode, buffering, encoding, errors,
FileNotFoundError: [Errno 2] No such file or directory: '/home/runner-manager/runner-fs/test-ydky3p5v-0-2723c1cbc900/runner-installed.timestamp'
unit-test-ydky3p5v-0: 06:49:30 ERROR unit.test-ydky3p5v/0.juju-log installed timestamp not found for runner test-ydky3p5v-0-2723c1cbc900, will not extract any metrics.
unit-test-ydky3p5v-0: 06:49:35 ERROR unit.test-ydky3p5v/0.juju-log Unable to get SSH connection for instance test-ydky3p5v-0-6a234bbdfebd, marking as unhealthy.
Traceback (most recent call last):
  File "/var/lib/juju/agents/unit-test-ydky3p5v-0/charm/venv/github_runner_manager/openstack_cloud/health_checks.py", line 130, in _get_ssh_connection
    ssh_conn = openstack_cloud.get_ssh_connection(instance)
  File "/var/lib/juju/agents/unit-test-ydky3p5v-0/charm/venv/github_runner_manager/openstack_cloud/openstack_cloud.py", line 138, in exception_handling_wrapper
    return func(*args, **kwargs)
  File "/var/lib/juju/agents/unit-test-ydky3p5v-0/charm/venv/github_runner_manager/openstack_cloud/openstack_cloud.py", line 324, in get_ssh_connection
    raise KeyfileError(
github_runner_manager.errors.KeyfileError: Missing keyfile for server: test-ydky3p5v-0-6a234bbdfebd, key path: /home/runner-manager/.ssh/test-ydky3p5v-0-6a234bbdfebd.key

The above exception was the direct cause of the following exception:

Traceback (most recent call last):
  File "/var/lib/juju/agents/unit-test-ydky3p5v-0/charm/venv/github_runner_manager/openstack_cloud/health_checks.py", line 49, in check_runner
    ssh_conn = _get_ssh_connection(openstack_cloud=openstack_cloud, instance=instance)
  File "/var/lib/juju/agents/unit-test-ydky3p5v-0/charm/venv/github_runner_manager/utilities.py", line 77, in fn_with_retry
    return func(*args, **kwargs)
  File "/var/lib/juju/agents/unit-test-ydky3p5v-0/charm/venv/github_runner_manager/openstack_cloud/health_checks.py", line 133, in _get_ssh_connection
    raise _SSHError(f"Unable to get SSH connection to {instance.server_name}") from exc
github_runner_manager.openstack_cloud.health_checks._SSHError: Unable to get SSH connection to test-ydky3p5v-0-6a234bbdfebd
unit-test-ydky3p5v-0: 06:49:39 ERROR unit.test-ydky3p5v/0.juju-log Unable to get SSH connection for instance test-ydky3p5v-0-6a234bbdfebd, marking as unhealthy.
Traceback (most recent call last):
  File "/var/lib/juju/agents/unit-test-ydky3p5v-0/charm/venv/github_runner_manager/openstack_cloud/health_checks.py", line 130, in _get_ssh_connection
    ssh_conn = openstack_cloud.get_ssh_connection(instance)
  File "/var/lib/juju/agents/unit-test-ydky3p5v-0/charm/venv/github_runner_manager/openstack_cloud/openstack_cloud.py", line 138, in exception_handling_wrapper
    return func(*args, **kwargs)
  File "/var/lib/juju/agents/unit-test-ydky3p5v-0/charm/venv/github_runner_manager/openstack_cloud/openstack_cloud.py", line 324, in get_ssh_connection
    raise KeyfileError(
github_runner_manager.errors.KeyfileError: Missing keyfile for server: test-ydky3p5v-0-6a234bbdfebd, key path: /home/runner-manager/.ssh/test-ydky3p5v-0-6a234bbdfebd.key

The above exception was the direct cause of the following exception:

Traceback (most recent call last):
  File "/var/lib/juju/agents/unit-test-ydky3p5v-0/charm/venv/github_runner_manager/openstack_cloud/health_checks.py", line 49, in check_runner
    ssh_conn = _get_ssh_connection(openstack_cloud=openstack_cloud, instance=instance)
  File "/var/lib/juju/agents/unit-test-ydky3p5v-0/charm/venv/github_runner_manager/utilities.py", line 77, in fn_with_retry
    return func(*args, **kwargs)
  File "/var/lib/juju/agents/unit-test-ydky3p5v-0/charm/venv/github_runner_manager/openstack_cloud/health_checks.py", line 133, in _get_ssh_connection
    raise _SSHError(f"Unable to get SSH connection to {instance.server_name}") from exc
github_runner_manager.openstack_cloud.health_checks._SSHError: Unable to get SSH connection to test-ydky3p5v-0-6a234bbdfebd
unit-test-ydky3p5v-0: 06:49:42 ERROR unit.test-ydky3p5v/0.juju-log Failed to get SSH connection while removing test-ydky3p5v-0-6a234bbdfebd
Traceback (most recent call last):
  File "/var/lib/juju/agents/unit-test-ydky3p5v-0/charm/venv/github_runner_manager/openstack_cloud/openstack_runner_manager.py", line 441, in _delete_runner
    ssh_conn = self._openstack_cloud.get_ssh_connection(instance)
  File "/var/lib/juju/agents/unit-test-ydky3p5v-0/charm/venv/github_runner_manager/openstack_cloud/openstack_cloud.py", line 138, in exception_handling_wrapper
    return func(*args, **kwargs)
  File "/var/lib/juju/agents/unit-test-ydky3p5v-0/charm/venv/github_runner_manager/openstack_cloud/openstack_cloud.py", line 324, in get_ssh_connection
    raise KeyfileError(
github_runner_manager.errors.KeyfileError: Missing keyfile for server: test-ydky3p5v-0-6a234bbdfebd, key path: /home/runner-manager/.ssh/test-ydky3p5v-0-6a234bbdfebd.key
unit-test-ydky3p5v-0: 06:49:49 CRITICAL unit.test-ydky3p5v/0.juju-log test mode is enabled

INFO     pytest_operator.plugin:plugin.py:1017 Forgetting model main...